Workbook

Sheet 안내
A1: 작은 섬의 영주 — 카드 목록 v0.6.6
A3: 시트 | B3: 내용
A4: 카드 목록 | B4: 카드 은행 161장(일반 137 · 카드사 24). 한 줄이 카드 한 장. "기본 덱"이 Y인 45장이 실제 게임에서 뽑혀요.
A5: 선택지별 성향 점수 | B5: 선택지 374개의 위험·시간·판단 점수. 음수는 안정/현재/자기판단 쪽, 양수는 도전/미래/타인참조 쪽. 어색한 점수는 노란 "검토 의견" 칸에 적어 주세요.
A6: 개념별 카드 수 | B6: 금융 개념마다 카드가 몇 장인지(수식으로 자동 계산). 얇은 개념에 새 카드를 우선 제안해 주세요.
A7: 새 카드 제안 | B7: 새 시나리오를 적는 칸. 예시 한 줄을 참고해 노란 칸을 채워 주세요.
A8: 순찰 소문 · 추가 선택지 | B8: v0.6 새 기능. 기본 덱 33장에 "순찰을 돌면 듣는 소문"이 붙었고, 그중 6장은 순찰 정중앙 성공 때 ✨추가 선택지가 열려요. 추가 선택지 효과 수치는 초안이라 노란 칸에 의견을 적어 주세요.
A10: 노란 칸 | B10: 팀원이 직접 적는 칸이에요. 나머지는 게임 데이터에서 옮겨 온 값이라 고치지 말아 주세요.
A11: 카드 작성 규칙 | B11: 상황은 2~3문장, 10~12세 어휘, 금융 용어 금지(할부·이자 같은 말은 선생님용 해설에서만). 선택지는 2~3개, 정답이 너무 뻔하지 않게.
A13: 게임 연결 (v0.6.6) | B13: 게임 v0.6.6은 data 폴더의 v2 파일을 읽어요. 파일로 열면 cards_bundle_v2.js, 웹 서버로 열면 cards_core_v2.json · cards_cardco_v2.json · deck_v2.json. 이 엑셀의 카드 161장 · 순찰 소문 33장 · 추가 선택지 6장은 v2 파일과 똑같아요(2026-10-06 대조).
A14: v0.6.6에서 바뀐 것 | B14: 카드 데이터는 v0.6.5와 같아요(카드 161장 · 순찰 소문 33장 · 추가 선택지 6장, 성향 점수 모두 그대로). 바뀐 건 게임 화면이에요 — 섬 장면을 320×180 픽셀로 새로 그렸고(scene_v2.html), 새로 지은 건물이 하늘에서 떨어져요. 플레이 중 섬은 늘 같은 자리·크기로 고정되고, 휴대폰에서 시작·동료 선택·플레이 화면에 스크롤이 생기지 않아요. 자세한 건 팀공유가이드 v0.6.6을 보세요.
A15: v0.6.5에서 바뀐 것 | B15: 카드 데이터는 v0.6.3과 같아요. 바뀐 건 게임 화면이에요 — 섬 장면 아래 프롬프트로 정보를 한 장씩 보여 주고, 휴대폰에서도 스크롤이 생기지 않아요. 자세한 건 팀공유가이드 v0.6.5를 보세요.

Sheet 카드 목록
A1: 카드 ID | B1: 구분 | C1: 숨은 개념 | D1: 보조 개념 | E1: 계절 이벤트 | F1: 난이도 | G1: 기본 덱 | H1: 제목 | I1: 상황 | J1: 선택지 1 | K1: 결과 1 | L1: 선택지 2 | M1: 결과 2 | N1: 선택지 3 | O1: 결과 3 | P1: 선생님용 해설 | Q1: 나오는 조건 | R1: 순찰 소문 (v0.6) | S1: ✨추가 선택지 (v0.6 · 초안)
A2: v3trade | B2: 일반 | C2: 위험과 수익 | E2: 무역철 | F2: 2 | G2: Y | H2: ⛵ 무역선 선장 | I2: 먼바다로 떠나는 무역선 선장이 왔어요. "금화를 맡기면 돌아올 때 두 배 반으로 갚겠소. 다만… 바다는 알 수 없지." 돌아올 확률은 반반이래요. | J2: 맡기지 않는다 [금화는 그대로] | K2: 선장은 어깨를 으쓱하고 떠났어요. 금화는 안전해요. | L2: 금화 10닢을 맡긴다 [절반은 남겨 둔다] | M2: 선장이 금화 10닢을 싣고 떠났어요. 가을이 되면 알게 될 거예요. | N2: 금화를 전부 맡긴다 [전부 걸면 전부 얻거나, 전부 잃거나] | O2: 금고가 텅 비었어요. 봄에 지을 것도, 급할 때 쓸 것도 없어요. 가을까지 기도해요. | P2: 기대값은 +25%지만 절반 확률로 전액 손실 — "잃어도 되는 만큼만"과 몰빵의 차이를 비교하게 한다. | R2: 항구 기록을 보니, 이 선장의 배는 지난 열 번 중 다섯 번만 돌아왔어요.
A3: v3seed | B3: 일반 | C3: 사기 예방 | E3: 풍년 | F3: 1 | G3: Y | H3: ✨ 황금 씨앗 장수 | I3: 번쩍이는 옷을 입은 장수가 왔어요. "이 황금 씨앗을 심으면 가을에 곡식이 세 배! 오늘만 금화 15닢. 다른 섬 영주들은 벌써 다 샀지요." | J3: 산다 [금화 −15] | K3: 씨앗을 심었어요. 정말 세 배가 될까요? | L3: 거절한다 ["세 배"는 수상해] | M3: 장수는 얼굴을 찡그리고 떠났어요. 나중에 들으니 그 씨앗은 그냥 색칠한 콩이었대요. | N3: 길드 상인에게 먼저 물어본다 [급할수록 확인] | O3: 길드 상인이 웃으며 말했어요. "그 사람, 지난달 세 섬에서 쫓겨났어요." 금화를 지켰어요. | P3: "무조건·오늘만·남들도 다 했다" 세 가지 신호가 모두 들어 있다. 어느 말이 수상했는지 짚어 보게 한다.
A4: v3drought | B4: 일반 | C4: 사후 대응 비용 | E4: 가뭄 | F4: 1 | G4: Y | H4: ☀️ 가뭄 | I4: 비가 한 달째 오지 않아요. 밭이 갈라지기 시작했어요. 이대로면 가을 수확이 절반으로 줄어요. | J4: 이웃 섬에서 물을 사 온다 [금화 −10, 수확은 지킴] | K4: 물을 사 와 밭을 살렸어요. 저수지가 있었다면 공짜였을 텐데요. | L4: 하늘에 맡긴다 [금화는 아낀다] | M4: 밭이 말라 갔어요. 가을 수확이 절반으로 줄 거예요. | P4: 저수지(15닢)를 미리 지은 섬과 물을 사는 섬(10닢/회)의 비용을 비교: 두 번 오면 사후 대응이 더 비싸다. | R4: 마을 노인 말로는, 이런 가뭄은 쉽게 그치지 않는대요.
A5: v3carriage | B5: 일반 | C5: 필요 vs 욕구 | E5: 축제 | F5: 1 | G5: Y | H5: 🎠 왕도의 마차 장수 | I5: 왕도에서 온 장수가 금박 마차를 팔아요. "영주라면 이 정도는 타셔야죠. 금화 15닢." 섬에는 마차가 달릴 길이 없긴 해요. | J5: 산다 [금화 −15] | K5: 마차는 멋졌어요. 사흘 동안은요. 지금은 항구 옆에 세워져 갈매기 쉼터가 됐어요. | L5: 사지 않는다 [길도 없는데] | M5: 장수는 실망했지만 금화 15닢은 금고에 남았어요. 겨울에 이 돈이 어떻게 쓰일지 두고 봐요. | P5: "영주라면 이 정도는" — 남의 시선 때문에 사는 소비. 필요한지 묻는 질문 하나면 충분하다. | R5: 이 장수는 다른 섬 세 곳에도 마차를 팔았는데, 다 항구 옆에 세워져 있대요. | S5: 마차 대신 섬에 길부터 놓을 수 있는지 묻는다 [금화는 그대로]
A6: v3guild | B6: 일반 | C6: 신용 · 대출 | E6: 흉년 | F6: 2 | G6: Y | H6: 📜 길드 상인의 제안 | I6: 길드 상인이 장부를 펼쳐요. "지금 곡식 20섬을 외상으로 드릴게요. 값은 다음 세 가을에 나눠 받지요. 물론 조금 얹어서요." 얹는 몫은 신뢰에 따라 달라요. | J6: 외상으로 곡식 20섬을 받는다 [지금 곡식 +20, 세 가을에 나눠 갚기] | K6: 곡식이 넉넉해졌어요. 대신 장부에 이름이 올랐어요. 매 가을 {pay}닢씩 갚아야 해요. | L6: 거절한다 [지금 곡식으로 충분] | M6: 상인은 장부를 덮었어요. "필요하면 언제든지요." 빚 없는 여름이에요. | P6: 곡식을 "지금" 받는 대가로 총액이 20→23~25로 는다. 신뢰가 높을수록 얹는 몫이 작은 것을 확인. | Q6: 신뢰 2↑ | R6: 길드 서기 말로는, 세 가을에 나눠 갚으면 받은 곡식보다 더 많이 갚게 된대요. | S6: 절반(10섬)만 외상으로 받는다 [지금 곡식 +10, 세 가을에 나눠 갚기 — 얹는 몫도 절반]
A7: v3neighbor | B7: 일반 | C7: 신용 · 대출 | E7: 흉년 | F7: 2 | G7: Y | H7: 🤝 이웃 섬 영주 | I7: 이웃 섬 영주가 배를 타고 왔어요. "곡식 10섬만 빌려주게. 가을에 12섬으로 갚겠네." 믿을 만한 사람이긴 한데, 그 섬도 형편이 어렵대요. | J7: 빌려준다 [곡식 −10, 가을에 12섬 (못 받을 수도)] | K7: 곡식 10섬을 실어 보냈어요. 가을에 12섬이 돌아올까요? | L7: 거절한다 [우리 겨울도 걱정] | M7: 영주는 이해한다며 돌아갔어요. 곡식은 그대로예요. | P7: 빌려주는 쪽에서 본 신용: 이자(2섬)는 떼일 위험(30%)의 값이다. | R7: 이웃 섬 창고를 본 어부 말로는, 그 섬 창고도 거의 비었대요. | S7: 5섬만 빌려준다 [곡식 −5, 가을에 6섬 (못 받을 수도)]
A8: v3fisher | B8: 일반 | C8: 소득 · 수입 늘리기 | E8: 평온한 날 | F8: 1 | G8: Y | H8: 🎣 어부의 부탁 | I8: 늙은 어부가 찾아왔어요. "배에 구멍이 났소. 금화 5닢만 대주면, 가을에 잡은 고기를 곡식 8섬 값으로 갚으리다." | J8: 금화 5닢을 대준다 [가을에 곡식 +8] | K8: 어부가 고맙다며 배를 고치러 갔어요. 작은 돈이지만 확실한 약속이에요. | L8: 거절한다 [금화 5닢도 아깝다] | M8: 어부는 조용히 돌아갔어요. 금화는 그대로예요. | P8: 작고 확실한 수익 — 무역선(크고 불확실)과 짝지어 비교하기 좋다. | R8: 이 어부는 평생 약속을 어긴 적이 없대요. 섬사람 모두가 아는 이야기예요.
A9: v3flood | B9: 일반 | C9: 분산 | E9: 폭우 | F9: 1 | G9: Y | H9: 🌧️ 폭우 | I9: 사흘 밤낮 비가 쏟아져 항구 쪽 밭이 물에 잠겼어요. | J9: 확인 | K9: 밭이 하나뿐이라 피해를 고스란히 입었어요. | P9: 선택지 없는 카드 — 결과가 봄의 선택(건너편 밭)에 이미 달려 있었다는 것을 보여 준다.
A10: sav01 | B10: 일반 | C10: 저축 · 비상금 | E10: 평온한 날 | F10: 1 | G10: Y | H10: 🫙 할머니의 항아리 | I10: 섬에서 제일 나이 많은 할머니가 빈 항아리를 주셨어요. "가을마다 한 줌씩 먼저 넣어 두렴. 남는 걸 넣는 게 아니라, 먼저 넣는 거야." | J10: 항아리에 곡식 5섬을 먼저 넣는다 [곡식 −5, 다음 가을에 돌려받음] | K10: 항아리 뚜껑을 꼭 닫았어요. 눈에 안 보이니 꺼내 먹을 생각도 안 나요. | L10: 항아리는 부엌 구석에 둔다 [나중에 남으면 넣지] | M10: 항아리는 한 번도 채워지지 않았어요. 남는 날이 오지 않았거든요. | P10: "쓰고 남은 돈을 저축"이 아니라 "저축하고 남은 돈을 쓰기". 선저축 원칙. | R10: 섬사람들 말로는, '남으면 넣지' 한 집은 항아리가 늘 비어 있었대요. | S10: 곡식 3섬만 먼저 넣는다 [곡식 −3, 다음 가을에 돌려받음]
A11: sav02 | B11: 일반 | C11: 저축 · 비상금 | E11: 태풍 | F11: 1 | H11: 🌀 태풍 소문과 비상 곡식 | I11: 먼바다에서 돌아온 어부가 수군거려요. "올해 바람이 이상해요." 광에 곡식을 따로 떼어 둘까 고민돼요. | J11: 비상 곡식 10섬을 언덕 위 광에 따로 둔다 [곡식 −10 (내년 가을 돌아옴), 이번 겨울 태풍 피해 줄어듦] | K11: 곡식 자루에 빨간 끈을 묶어 언덕 위로 옮겼어요. "이건 정말 급할 때만!" | L11: 그냥 둔다 [어차피 다 같은 곡식] | M11: 곡식은 곡식이죠. 딱히 달라진 건 없어요. | P11: 비상금은 "따로 이름 붙이고 따로 둔 돈". 당장 쓸 수 있는 곡식은 줄지만 재난이 와도 버틸 몫이 남는다.
A12: sav03 | B12: 일반 | C12: 저축 · 비상금 | D12: 필요 vs 욕구 | E12: 풍년 | F12: 1 | G12: Y | H12: 🌾 풍년 잔치 | I12: 올해는 벼가 고개를 푹 숙였어요. 섬사람들이 "잔치를 열자!"고 외쳐요. 잔치엔 곡식 12섬이 들어요. | J12: 크게 잔치를 연다 [곡식 −12] | K12: 밤새 북소리가 울렸어요. 다음 날 광을 보니 휑하네요. | L12: 작게 열고 나머지는 모아 둔다 [곡식 −4] | M12: 소박한 잔치였지만 다들 즐거웠어요. 광에는 곡식이 넉넉히 남았어요. | N12: 잔치 대신 창고를 손본다 [금화 −5, 곡식이 덜 썩음] | O12: 잔치는 없었지만 창고 틈을 막았어요. 이번 가을엔 넘치는 곡식이 덜 썩을 거예요. | P12: 수입이 많은 해일수록 저축 기회. "좋은 해에 모아 나쁜 해를 버틴다." | R12: 작년에 크게 잔치한 이웃 섬은 겨울에 곡식을 빌리러 다녔대요.
A13: sav04 | B13: 일반 | C13: 저축 · 비상금 | E13: 한파 | F13: 2 | H13: ❄️ 땔감 모으기 | I13: 철새가 일찍 떠났어요. 겨울이 길 거래요. 여름에 땔감을 해 두면 겨울에 곡식을 덜 먹는대요. 하지만 땔감을 하느라 밭일을 덜 하게 돼요. | J13: 땔감을 넉넉히 해 둔다 [가을 수확 −5, 겨울 식량 −4] | K13: 땀 흘려 장작을 쌓았어요. 밭은 좀 덜 돌봤지만 겨울이 두렵지 않아요. | L13: 밭일에 집중한다 [수확은 그대로] | M13: 밭은 반짝반짝해요. 겨울 땔감은… 그때 가서 생각하죠. | P13: 오늘의 소득을 조금 줄여 미래의 필수 지출을 줄이는 선택. 효과는 1섬 차이지만 "나중을 위해 지금 덜 쓴다"를 체험.
A14: sav05 | B14: 일반 | C14: 저축 · 비상금 | D14: 예산, 비교 구매 | E14: 축제 | F14: 2 | H14: 🎪 떠돌이 서커스 | I14: 떠돌이 서커스단이 항구에 천막을 쳤어요. 표 한 장에 금화 8닢. 아이들이 줄을 섰어요. 금고엔 가을 장부의 날에 낼 돈이 들어 있어요. | J14: 표를 산다 [금화 −8] | K14: 곡예사가 공중에서 세 바퀴를 돌았어요! 정말 멋졌어요. 금고는 조금 가벼워졌어요. | L14: 이번엔 안 간다 [금화 그대로] | M14: 천막 밖에서 음악만 들었어요. 조금 아쉽지만 금고는 든든해요. | N14: 마지막 날 싼 표를 산다 [금화 −3, 하루 기다리기] | O14: 마지막 날엔 표가 3닢이었어요! 기다린 보람이 있었어요. | P14: 즐기는 소비 자체는 나쁘지 않다. 문제는 "먼저 떼어 둔 돈"(결제일 몫)을 건드리느냐. 기다리면 싸지는 것도 체험.
A15: sav06 | B15: 일반 | C15: 저축 · 비상금 | D15: 물가 | E15: 흉년 | F15: 2 | H15: 🍂 흉년의 이웃 섬 | I15: 이웃 섬이 흉년이래요. 그 섬 영주는 작년에 창고 없이 풍년 곡식을 다 팔아 버렸대요. 우리 섬 광을 보니 곡식이 꽤 남아 있어요. | J15: 광을 한 번 더 점검하고 틈을 막는다 [금화 −4] | K15: 쥐구멍 세 개를 막았어요. 곡식이 새지 않아요. | L15: 남는 곡식을 비싸게 판다 [곡식 −10, 금화 +15] | M15: 흉년이라 곡식값이 올랐어요! 금화 15닢을 받았어요. 겨울은… 괜찮겠죠? | N15: 아무것도 안 한다 | O15: 남의 일이죠, 뭐. 광은 그대로예요. | P15: 남의 실패에서 배우기 + 값이 오를 때 파는 유혹. 비상금은 팔아 치우는 순간 비상금이 아니다.
A16: sav07 | B16: 일반 | C16: 저축 · 비상금 | D16: 사후 대응 비용, 보험 | E16: 화재 | F16: 3 | H16: 🔥 대장간 화재 | I16: 밤중에 대장간에서 불이 나 옆 광까지 번졌어요! 곡식을 한곳에만 쌓아 둔 섬은 크게 잃었대요. 우리 섬도 불씨가 날아왔어요. | J16: 물을 퍼 나른다 [곡식 −6] | K16: 밤새 물을 날랐어요. 광 한쪽이 그을렸지만 곡식 대부분을 지켰어요. | L16: 금화로 소방대를 부른다 [금화 −8] | M16: 이웃 섬 소방대가 배를 타고 와 불을 껐어요. 곡식은 멀쩡하지만 금화가 들었어요. | P16: 저축도 "어디에 어떻게" 두느냐가 중요하다. 안전한 보관(창고=예금자보호가 있는 계좌) vs 집에 쌓아 두기.
A17: sav08 | B17: 일반 | C17: 저축 · 비상금 | D17: 소득 · 수입 늘리기, 기회비용 | E17: 이주민 | F17: 3 | H17: 🧳 새로 온 가족 | I17: 폭풍에 집을 잃은 가족이 섬에 살고 싶대요. 일손이 늘면 다음 해부터 수확이 늘어요. 하지만 올겨울엔 입이 늘어 곡식이 더 들어요. | J17: 받아들인다 [올겨울 식량 +4, 내년부터 수확 +4] | K17: 가족이 짐을 풀었어요. 올겨울은 빠듯하겠지만 내년 밭이 기대돼요. | L17: 다음 해에 오라고 한다 | M17: 가족은 다른 섬으로 떠났어요. 우리 겨울은 조금 편해졌어요. | P17: 비상금이 있어야 "지금 조금 손해, 나중에 이득"인 기회를 잡을 수 있다. 여유 없는 섬은 좋은 기회도 못 잡는다.
A18: sav09 | B18: 일반 | C18: 저축 · 비상금 | D18: 유동성 · 만기 | E18: 평온한 날 | F18: 1 | H18: 🐷 돼지 저금통 조개 | I18: 해변에서 구멍 뚫린 큰 조개를 주웠어요. 금화를 넣으면 깨야만 꺼낼 수 있대요. 아이들이 "영주님도 하나 해요!" 해요. | J18: 금화 6닢을 넣고 봉한다 [금화 −6, 내년 가을에 돌려받음] | K18: 달그락. 조개가 무거워졌어요. 깨고 싶은 마음이 들 때마다 참아요. | L18: 필요 없다 [금고가 있잖아] | M18: 아이들이 시무룩해요. 금고의 금화는 여전히 쉽게 꺼낼 수 있어요. | P18: 꺼내기 어렵게 만드는 장치(적금·자동이체)가 저축을 돕는다. 대신 급할 때 못 쓴다는 점도 짚기(유동성).
A19: cmp01 | B19: 일반 | C19: 이자 · 복리 | E19: 평온한 날 | F19: 1 | G19: Y | H19: 🏦 길드 금고의 약속 | I19: 길드 상인이 말해요. "금화를 금고에 맡기면 가을마다 열 닢에 한 닢씩 얹어 드려요. 대신 맡긴 동안엔 못 꺼내요." | J19: 금화 10닢을 맡긴다 [이번 가을에 11닢으로] | K19: 금고 열쇠가 딸깍. 가만히 있어도 금화가 늘어난대요. | L19: 금고에 맡기지 않는다 [금화는 손에] | M19: 금화는 손에 있어요. 늘지도 줄지도 않아요. | P19: 이자의 첫 체험: "돈을 빌려주면(맡기면) 값을 받는다". 은행 예금의 원리. | R19: 길드 금고는 백 년째 문을 열었고, 약속을 어긴 적이 없대요.
A20: cmp02 | B20: 일반 | C20: 이자 · 복리 | D20: 유동성 · 만기 | E20: 평온한 날 | F20: 2 | G20: Y | H20: 🌳 두 번 맡기기 | I20: 길드 상인이 장부를 보여 줘요. "한 해만 맡기면 10닢이 11닢. 그런데 두 해 두면, 늘어난 11닢에 또 얹어서 12닢이 넘어요. 세 해면요…?" | J20: 한 해만 맡긴다 [금화 −10 → 이번 가을 11] | K20: 한 해짜리 약속을 했어요. | L20: 두 해 맡긴다 [금화 −10 → 내년 가을 13] | M20: 두 해짜리 약속을 했어요. 늘어난 금화에 또 얹힌대요. | N20: 맡기지 않는다 | O20: 금화는 손에 그대로예요. | P20: 단리(매년 +1)면 2년 후 12, 복리면 12.1→반올림·보너스로 13. 오래 둘수록 차이가 커지는 게 복리. 은행나무 대안의 핵심을 한 장으로 흡수. | R20: 길드 장부를 보니, 오래 맡길수록 늘어난 금화에 또 얹혀서 점점 빨리 불어나요.
A21: cmp03 | B21: 일반 | C21: 이자 · 복리 | E21: 풍년 | F21: 2 | H21: 🌱 볍씨 남기기 | I21: 풍년이에요. 늙은 농부가 말해요. "먹을 걸 다 먹지 말고 좋은 볍씨를 남기게. 볍씨는 내년에 몇 배로 돌아오니까." | J21: 좋은 볍씨 6섬을 남긴다 [곡식 −6, 내년 가을 +10] | K21: 제일 튼실한 이삭만 골라 따로 말렸어요. | L21: 다 먹는다 [지금 배부르게] | M21: 오늘 저녁은 배불러요. 볍씨는 시장에서 또 사면 되죠. | P21: 원금(씨앗)을 먹어 치우지 않는 것이 불어남의 시작. 씨앗 = 원금, 수확 = 이자.
A22: cmp04 | B22: 일반 | C22: 이자 · 복리 | D22: 유동성 · 만기, 필요 vs 욕구 | E22: 무역철 | F22: 3 | H22: 📈 맡긴 금화를 꺼낼까 | I22: 작년에 길드 금고에 맡긴 금화가 잘 늘고 있어요. 그런데 항구에 멋진 망원경이 들어왔어요. 지금 꺼내면 얹힌 몫은 하나도 못 받는대요. | J22: 그대로 둔다 [내년 가을에 크게] | K22: 망원경은 멋졌지만 참았어요. 금고 속 금화는 계속 불어나요. | L22: 꺼내서 망원경을 산다 [금화 +10 → 곧바로 −10] | M22: 망원경으로 먼 섬이 보여요! 금고의 약속은 끝났어요. | P22: 복리는 "중간에 꺼내지 않을 때"만 작동한다. 중도해지 = 이자 포기. | Q22: 2년차부터
A23: cmp05 | B23: 일반 | C23: 이자 · 복리 | D23: 기회비용 | E23: 축제 | F23: 1 | G23: Y | H23: 🎁 두 가지 선물 | I23: 축제날, 길드장이 두 선물 중 하나를 고르래요. "지금 금화 10닢을 받든지, 내년 가을에 15닢을 받든지." | J23: 지금 10닢 [금화 +10] | K23: 금화 10닢이 짤랑! 바로 쓸 수 있어요. | L23: 내년 가을 15닢 [기다리기] | M23: 길드장이 웃으며 약속 증서를 줬어요. "기다릴 줄 아는 영주군요." | P23: 시간의 가치: 지금의 10 vs 나중의 15. 어느 쪽이 정답은 아니다 — 지금 급한 게 있는지가 기준. | R23: 길드장은 약속 증서를 한 번도 어긴 적이 없대요. 내년 가을엔 정말 15닢이에요.
A24: cmp06 | B24: 일반 | C24: 이자 · 복리 | D24: 소득 · 수입 늘리기 | E24: 한파 | F24: 2 | H24: 🐑 양 두 마리 | I24: 양치기가 새끼 밴 양 두 마리를 금화 12닢에 판대요. "양은 양을 낳고, 그 양이 또 양을 낳지요." 겨울 먹이도 조금 들어요. | J24: 산다 [금화 −12, 겨울 식량 +2, 이후 매년 곡식] | K24: 양 두 마리가 섬에 왔어요. 매에에! | L24: 사지 않는다 | M24: 양치기는 다른 섬으로 떠났어요. | P24: 불어나는 자산(새끼를 낳는 양) vs 줄어드는 소비. 해가 갈수록 수입이 커지는 게 복리의 모양.
A25: cmp07 | B25: 일반 | C25: 이자 · 복리 | D25: 유동성 · 만기, 보험 | E25: 역병 | F25: 3 | H25: 💊 금고를 깰까 | I25: 역병 소문이 돌아요. 약초를 미리 사 두려면 금화가 필요한데, 금화 대부분은 길드 금고에 맡겨 두었어요. 지금 꺼내면 얹힌 몫을 못 받아요. | J25: 금고를 깨서 약초를 산다 [금화 −6, 이번 겨울 역병 대비] | K25: 얹힌 몫은 날아갔지만 약초 자루가 든든해요. | L25: 금고는 두고 버틴다 | M25: 금고 속 금화는 계속 불어나요. 역병이 안 오기를 바라요. | P25: 비상금(바로 꺼낼 돈)과 불리는 돈(묶인 돈)을 나눠야 하는 이유. 둘 다 필요하다. | Q25: 2년차부터
A26: cmp08 | B26: 일반 | C26: 이자 · 복리 | E26: 평온한 날 | F26: 3 | H26: 🧮 영주의 계산 시합 | I26: 섬 학교 선생님이 문제를 냈어요. "금화 10닢이 해마다 열 닢에 한 닢씩 늘면, 30년 뒤엔 몇 닢일까요?" 맞히면 상으로 금화를 준대요. | J26: "40닢이요!" [해마다 1닢씩 더하면…] | K26: 선생님이 고개를 저어요. "늘어난 돈에도 또 붙는다는 걸 잊었구나. 정답은 170닢이 넘어!" | L26: "100닢도 넘을 거예요" [늘어난 돈에도 또 붙으니까] | M26: "맞았어요! 174닢이 넘어요. 시간이 제일 큰 일꾼이지요." 상으로 금화 5닢을 받았어요. | P26: 10×1.1^30 ≈ 174. 단리(40)와 복리(174)의 차이를 숫자로 확인하는 유일한 카드 — 수업 중 계산기와 함께.
A27: ins01 | B27: 일반 | C27: 보험 | E27: 태풍 | F27: 1 | G27: Y | H27: 🛡️ 파도막이 조합 | I27: 이웃 섬 영주 다섯이 모였어요. "해마다 금화 5닢씩 모아 두고, 올겨울 태풍 맞은 섬이 있으면 그 돈으로 도와주자!" | J27: 조합에 들어간다 [금화 −5, 이번 겨울 태풍 피해 줄어듦] | K27: 다섯 섬이 손을 모았어요. 태풍이 와도 혼자가 아니에요. | L27: 들어가지 않는다 [5닢이 아까워] | M27: "태풍이 안 오면 5닢만 버리는 거잖아." 금화는 그대로예요. | P27: 보험의 원리 = 여럿이 조금씩 내서 운 나쁜 한 명의 큰 손실을 나눠 진다. 안 오면 "버린 돈"이 아니라 "안심을 산 값". | R27: 작년에 조합에 든 섬들은 태풍을 맞고도 다음 봄에 다시 일어섰대요.
A28: ins02 | B28: 일반 | C28: 보험 | E28: 역병 | F28: 1 | H28: 🌿 약초꾼의 제안 | I28: 약초꾼이 말해요. "금화 4닢이면 역병 약초를 한 바구니 드리지요. 역병이 안 돌면 그냥 차로 끓여 드세요." | J28: 산다 [금화 −4, 이번 겨울 역병 대비] | K28: 향긋한 약초 바구니를 광에 걸었어요. | L28: 안 산다 [역병 소문은 늘 있지] | M28: 약초꾼은 다음 섬으로 갔어요. | P28: 작은 비용(4닢)으로 큰 손실(곡식 −10, 금화 −10)을 줄이는 선택. 예보를 보고 판단하게 한다.
A29: ins03 | B29: 일반 | C29: 보험 | D29: 계약 · 약관 | E29: 태풍 | F29: 2 | H29: ⚓ 배 지킴이 계약 | I29: 해운 조합이 말해요. "매 가을 금화 3닢씩 내면, 태풍에 배가 부서졌을 때 수리비를 대 드립니다. 세 해 동안 약속하는 조건이에요." | J29: 세 해 약속을 맺는다 [매 가을 금화 −3, 태풍 대비] | K29: 서명했어요. 태풍이 와도 배 수리비 걱정은 없어요. | L29: 안 맺는다 | M29: 해운 조합 사람은 명함만 두고 갔어요. | P29: 보험료는 한 번이 아니라 "계속" 낸다. 첫해만 보장이 되고 둘째 해엔 돈만 나가는 구조 — 약관을 읽어야 보인다는 점까지 토론 가능.
A30: ins04 | B30: 일반 | C30: 보험 | D30: 사후 대응 비용 | E30: 가뭄 | F30: 2 | H30: 🪣 물 저장 항아리 | I30: 가뭄 기미가 보여요. 옹기장이가 큰 물항아리를 팔아요. "비 올 때 받아 두면 가뭄에 밭을 살릴 수 있어요. 6닢." | J30: 항아리를 산다 [금화 −6] | K30: 빗물을 가득 받아 두었어요. 가뭄이 와도 한 번은 버틸 수 있어요. | L30: 안 산다 | M30: 밭이 쩍쩍 갈라지기 시작했어요. 가을 수확이 줄 거예요. | P30: 사전 비용 6닢 vs 사후 손실(수확 절반 ≈ 10섬). 저수지가 있으면 중복 보험은 필요 없다는 점도 체험.
A31: ins05 | B31: 일반 | C31: 보험 | E31: 평온한 날 | F31: 2 | G31: Y | H31: 🧾 아까운 5닢 | I31: 작년에 파도막이 조합에 5닢을 냈는데 태풍이 안 왔어요. 올해도 내라는데 섬사람들이 투덜대요. "작년 5닢은 버린 거잖아요!" | J31: 올해도 낸다 [금화 −5, 태풍 대비] | K31: "안 온 건 운이 좋았던 거야." 올해도 조합에 들었어요. | L31: 올해는 안 낸다 [금화 절약] | M31: 5닢을 아꼈어요. 올겨울 바다가 조용하길 바라요. | P31: "보험료가 아깝다"는 감정을 정면으로 다루는 카드. 보험은 결과가 아니라 결정 시점의 정보로 평가해야 한다. | Q31: 2년차부터 | R31: 작년에 조합을 그만둔 이웃 섬이 올해 태풍을 혼자 맞았대요.
A32: ins06 | B32: 일반 | C32: 보험 | D32: 정보의 가치 · 예측 | E32: 한파 | F32: 1 | H32: 🧣 털옷 장수 | I32: 털옷 장수가 왔어요. "혹한이 오면 섬사람들이 앓아누워요. 털옷을 미리 사 두면 곡식을 덜 잃어요. 5닢." | J32: 털옷을 산다 [금화 −5, 이번 겨울 혹한 대비] | K32: 포근한 털옷을 나눠 줬어요. | L32: 안 산다 | M32: 털옷 장수는 다음 섬으로 갔어요. | P32: 예보와 연결해서 판단하게 한다. 예보가 혹한일 때만 사는 게 합리적인가? (예보는 75%만 맞는다)
A33: ins07 | B33: 일반 | C33: 보험 | D33: 위험과 수익 | E33: 화재 | F33: 3 | H33: 🧯 모래주머니 약속 | I33: 대장간 주인이 제안해요. "우리 대장간에 불이 나면 섬 전체가 위험해요. 금화 3닢씩 모아 모래주머니를 쌓아 두면 어때요?" 그런데 대장간 불이 우리 섬까지 번진 적은 없어요. | J33: 3닢을 낸다 [금화 −3] | K33: 모래주머니가 차곡차곡 쌓였어요. | L33: 안 낸다 | M33: 대장간 주인이 한숨을 쉬었어요. | P33: 확률 20%의 사고: 대비 3닢(손실 −2) vs 무대비(손실 −12). 기대 손실 비교(0.2×12=2.4 > 3?)로 "보험이 항상 이득은 아니다"까지 토론.
A34: ins08 | B34: 일반 | C34: 보험 | D34: 기회비용, 정보의 가치 · 예측 | E34: 태풍 | F34: 3 | G34: Y | H34: 🏚️ 방파제 대신 보험 상인 | I34: 보험 상인이 왔어요. "방파제는 25닢이나 들죠? 저한테 매 가을 5닢만 내세요. 태풍이 오면 제가 피해를 막아 드려요." 올해는 태풍 예보가 없어요. | J34: 상인과 계약한다 [금화 −5, 이번 겨울 태풍 대비] | K34: 계약서를 받았어요. 방파제보다 싸게 먹혔어요… 올해는요. | L34: 방파제를 짓기로 하고 거절한다 [봄에 짓기] | M34: "한 번 지으면 계속 지켜 주니까요." 상인은 떠났어요. | N34: 아무것도 안 한다 [올해는 예보가 없으니까] | O34: 예보가 틀릴 수도 있다는 게 마음에 걸려요. | P34: 매년 내는 보험료(5×3=15) vs 한 번에 짓는 방파제(25, 영구). 기간이 길수록 어느 쪽이 싼지 계산하게 한다. | R34: 계약서 뒷면을 보니, 매 가을 5닢을 계속 내야 지켜 준대요. 방파제는 한 번 지으면 끝이고요.
A35: ins09 | B35: 일반 | C35: 보험 | D35: 사후 대응 비용 | E35: 역병 | F35: 2 | H35: 🐀 쥐 떼 소문 | I35: 이웃 섬에 쥐 떼가 나타나 병이 돌았대요. 고양이 두 마리를 금화 6닢에 들여올 수 있어요. 고양이는 먹이도 조금 먹어요. | J35: 고양이를 들인다 [금화 −6, 겨울 식량 +1, 역병 대비] | K35: 야옹. 쥐들이 겁을 먹고 숨었어요. | L35: 들이지 않는다 | M35: 밤마다 광에서 바스락 소리가 나요. | P35: 보험만 있는 게 아니라 "위험 자체를 줄이는" 예방도 위험관리다.
A36: div01 | B36: 일반 | C36: 분산 | E36: 폭우 | F36: 1 | G36: Y | H36: 🧺 달걀 바구니 | I36: 닭장 아이가 달걀 20개를 시장에 가져가려 해요. "바구니 하나에 다 담을까, 두 개에 나눠 담을까?" 길이 미끄러워요. | J36: 한 바구니에 다 담는다 [한 번에 들고 가기 편함] | K36: 아이가 넘어졌어요! 달걀이 전부 깨졌어요. 금화 4닢어치예요. | L36: 두 바구니에 나눈다 [두 번 왔다 갔다] | M36: 한 번 넘어졌지만 다른 바구니는 멀쩡했어요. 금화 2닢어치만 잃었어요. | P36: "한 바구니에 달걀을 담지 마라"를 말 그대로 체험. 결과가 확정적인 입문 카드. | R36: 아침에 비가 와서, 시장 가는 언덕길이 진흙탕이래요.
A37: div02 | B37: 일반 | C37: 분산 | D37: 위험과 수익 | E37: 무역철 | F37: 2 | G37: Y | H37: ⛵ 배 두 척에 나눠 싣기 | I37: 곡식 12섬을 이웃 섬에 팔러 보내요. 큰 배 한 척에 다 실을까, 작은 배 두 척에 나눠 실을까? 바다가 거칠 때도 있어요. | J37: 큰 배 한 척 [곡식 −12, 반반 확률로 금화 20 또는 0] | K37: 큰 배가 출항했어요. | L37: 작은 배 두 척 [곡식 −12, 대부분 금화 10~20] | M37: 작은 배 두 척이 따로 떠났어요. | N37: 보내지 않는다 | O37: 곡식은 광에 그대로예요. | P37: 같은 기대 수익이어도 나누면 "다 잃을 확률"이 40%→16%로 준다. 분산은 수익을 키우는 게 아니라 흔들림을 줄인다. | Q37: 곡식 20↑ | R37: 뱃사람들 말로는, 거친 바다에서 두 척이 한꺼번에 가라앉는 일은 드물대요.
A38: div03 | B38: 일반 | C38: 분산 | D38: 위험과 수익, 사기 예방 | E38: 역병 | F38: 2 | H38: 🌽 한 가지 작물 | I38: 씨앗 장수가 말해요. "올해는 옥수수가 대박이에요! 밭을 전부 옥수수로 바꾸세요." 옥수수는 병에 약하대요. | J38: 전부 옥수수로 바꾼다 [가을 수확 크게 흔들림] | K38: 밭이 온통 옥수수예요. | L38: 절반만 바꾼다 [가을 수확 조금 흔들림] | M38: 옥수수 반, 벼 반. 밭이 알록달록해요. | N38: 하던 대로 한다 | O38: 밭은 늘 그렇듯 벼가 가득해요. | P38: "대박"이라는 말과 함께 오는 몰빵 유혹. 절반만 바꾸면 기대값은 더 높고(+1.5) 최악은 −3에 그친다.
A39: div04 | B39: 일반 | C39: 분산 | D39: 보험, 기회비용 | E39: 태풍 | F39: 3 | H39: 🏝️ 두 섬에 광 짓기 | I39: 작은 무인도 하나가 매물로 나왔어요. 거기 광을 지으면 곡식을 두 섬에 나눠 둘 수 있어요. 금화 12닢. | J39: 무인도에 광을 짓는다 [금화 −12, 이번 겨울 모든 재난 피해 줄어듦] | K39: 작은 광이 생겼어요. 곡식 절반을 옮겨 두었어요. | L39: 그 돈으로 방파제를 준비한다 [봄에 짓기] | M39: 한 곳을 튼튼히 지키기로 했어요. | N39: 필요 없다 | O39: 무인도는 다른 영주가 샀어요. | P39: 분산은 재난 "종류"를 가리지 않고 피해를 줄인다(any). 특정 보험(방파제)과 비교: 넓고 얕게 vs 좁고 깊게. | Q39: 2년차부터
A40: div05 | B40: 일반 | C40: 분산 | D40: 소득 · 수입 늘리기 | E40: 풍년 | F40: 1 | H40: 🍎 과수원 아저씨 | I40: 과수원 아저씨가 사과나무 묘목을 나눠 준대요. 벼만 키우던 밭 한쪽에 심을 수 있어요. 대신 벼 수확이 조금 줄어요. | J40: 사과나무를 심는다 [올해 수확 −3, 내년 가을 곡식 +8] | K40: 밭 한쪽에 작은 묘목들이 줄지어 섰어요. | L40: 벼만 키운다 | M40: 밭은 여전히 벼로 가득해요. | P40: 다른 시기·다른 위험에 반응하는 수입원을 더하면 한 해 흉년이 섬 전체를 흔들지 않는다.
...

Sheet 선택지별 성향 점수
A1: 카드 ID | B1: 제목 | C1: 번호 | D1: 선택지 | E1: 효과 힌트 | F1: 위험 (안정− / 도전+) | G1: 시간 (현재− / 미래+) | H1: 판단 (자기− / 타인+) | I1: 읽기 쉽게 | J1: 점수 근거 | K1: 검토 의견
A2: v3trade | B2: 무역선 선장 | C2: 1 | D2: 맡기지 않는다 | E2: 금화는 그대로 | F2: -1 | G2: 0 | H2: 0 | I2: 안정 -1
A3: v3trade | B3: 무역선 선장 | C3: 2 | D3: 금화 10닢을 맡긴다 | E3: 절반은 남겨 둔다 | F3: 0 | G3: 0 | H3: 0 | I3: 성향 무관 | J3: 위험:걸기 시간:결과가나중(잠금)
A4: v3trade | B4: 무역선 선장 | C4: 3 | D4: 금화를 전부 맡긴다 | E4: 전부 걸면 전부 얻거나, 전부 잃거나 | F4: 1 | G4: 0 | H4: 0 | I4: 도전 +1 | J4: 위험:걸기(전부) 시간:결과가나중(잠금)
A5: v3seed | B5: 황금 씨앗 장수 | C5: 1 | D5: 산다 | E5: 금화 −15 | F5: 1 | G5: 0 | H5: 1 | I5: 도전 +1 · 타인참조 +1 | J5: 위험:고수익약속수용 판단:타인참조
A6: v3seed | B6: 황금 씨앗 장수 | C6: 2 | D6: 거절한다 | E6: "세 배"는 수상해 | F6: 0 | G6: 0 | H6: -1 | I6: 자기판단 -1 | J6: 판단:자기판단
A7: v3seed | B7: 황금 씨앗 장수 | C7: 3 | D7: 길드 상인에게 먼저 물어본다 | E7: 급할수록 확인 | F7: 0 | G7: 0 | H7: 1 | I7: 타인참조 +1 | J7: 판단:타인참조
A8: v3drought | B8: 가뭄 | C8: 1 | D8: 이웃 섬에서 물을 사 온다 | E8: 금화 −10, 수확은 지킴 | F8: -1 | G8: 0 | H8: 0 | I8: 안정 -1
A9: v3drought | B9: 가뭄 | C9: 2 | D9: 하늘에 맡긴다 | E9: 금화는 아낀다 | F9: 1 | G9: 0 | H9: 0 | I9: 도전 +1 | J9: 위험:대비안함
A10: v3carriage | B10: 왕도의 마차 장수 | C10: 1 | D10: 산다 | E10: 금화 −15 | F10: 0 | G10: -1 | H10: 1 | I10: 현재 -1 · 타인참조 +1 | J10: 시간:지금소비 판단:타인참조
A11: v3carriage | B11: 왕도의 마차 장수 | C11: 2 | D11: 사지 않는다 | E11: 길도 없는데 | F11: 0 | G11: 1 | H11: -1 | I11: 미래 +1 · 자기판단 -1 | J11: 판단:자기판단
A12: v3guild | B12: 길드 상인의 제안 | C12: 1 | D12: 외상으로 곡식 20섬을 받는다 | E12: 지금 곡식 +20, 세 가을에 나눠 갚기 | F12: 0 | G12: -1 | H12: 0 | I12: 현재 -1 | J12: 시간:외상·할부
A13: v3guild | B13: 길드 상인의 제안 | C13: 2 | D13: 거절한다 | E13: 지금 곡식으로 충분 | F13: 0 | G13: 1 | H13: 0 | I13: 미래 +1
A14: v3neighbor | B14: 이웃 섬 영주 | C14: 1 | D14: 빌려준다 | E14: 곡식 −10, 가을에 12섬 (못 받을 수도) | F14: 1 | G14: 0 | H14: 0 | I14: 도전 +1 | J14: 위험:걸기 시간:결과가나중(잠금)
A15: v3neighbor | B15: 이웃 섬 영주 | C15: 2 | D15: 거절한다 | E15: 우리 겨울도 걱정 | F15: -1 | G15: 0 | H15: 0 | I15: 안정 -1
A16: v3fisher | B16: 어부의 부탁 | C16: 1 | D16: 금화 5닢을 대준다 | E16: 가을에 곡식 +8 | F16: 0 | G16: 1 | H16: 0 | I16: 미래 +1 | J16: 시간:나중보상
A17: v3fisher | B17: 어부의 부탁 | C17: 2 | D17: 거절한다 | E17: 금화 5닢도 아깝다 | F17: 0 | G17: -1 | H17: 0 | I17: 현재 -1
A18: v3flood | B18: 폭우 | C18: 1 | D18: 확인 | F18: 0 | G18: 0 | H18: 0 | I18: 성향 무관
A19: sav01 | B19: 할머니의 항아리 | C19: 1 | D19: 항아리에 곡식 5섬을 먼저 넣는다 | E19: 곡식 −5, 다음 가을에 돌려받음 | F19: 0 | G19: 1 | H19: 1 | I19: 미래 +1 · 타인참조 +1 | J19: 시간:나중보상 판단:타인참조
A20: sav01 | B20: 할머니의 항아리 | C20: 2 | D20: 항아리는 부엌 구석에 둔다 | E20: 나중에 남으면 넣지 | F20: 0 | G20: -1 | H20: -1 | I20: 현재 -1 · 자기판단 -1 | J20: 판단:자기판단
A21: sav02 | B21: 태풍 소문과 비상 곡식 | C21: 1 | D21: 비상 곡식 10섬을 언덕 위 광에 따로 둔다 | E21: 곡식 −10 (내년 가을 돌아옴), 이번 겨울 태풍 피해 줄어듦 | F21: -1 | G21: 1 | H21: 0 | I21: 안정 -1 · 미래 +1 | J21: 위험:재난대비 시간:나중보상
A22: sav02 | B22: 태풍 소문과 비상 곡식 | C22: 2 | D22: 그냥 둔다 | E22: 어차피 다 같은 곡식 | F22: 1 | G22: -1 | H22: 0 | I22: 도전 +1 · 현재 -1
A23: sav03 | B23: 풍년 잔치 | C23: 1 | D23: 크게 잔치를 연다 | E23: 곡식 −12 | F23: 0 | G23: -1 | H23: 0 | I23: 현재 -1 | J23: 시간:지금소비
A24: sav03 | B24: 풍년 잔치 | C24: 2 | D24: 작게 열고 나머지는 모아 둔다 | E24: 곡식 −4 | F24: 0 | G24: 1 | H24: 0 | I24: 미래 +1 | J24: 시간:지금소비 시간:기다림·떼어둠
A25: sav03 | B25: 풍년 잔치 | C25: 3 | D25: 잔치 대신 창고를 손본다 | E25: 금화 −5, 곡식이 덜 썩음 | F25: 0 | G25: 0 | H25: 0 | I25: 성향 무관 | J25: 위험:보관
A26: sav04 | B26: 땔감 모으기 | C26: 1 | D26: 땔감을 넉넉히 해 둔다 | E26: 가을 수확 −5, 겨울 식량 −4 | F26: 0 | G26: 0 | H26: 0 | I26: 성향 무관 | J26: 시간:미래지출절감
A27: sav04 | B27: 땔감 모으기 | C27: 2 | D27: 밭일에 집중한다 | E27: 수확은 그대로 | F27: 0 | G27: 0 | H27: 0 | I27: 성향 무관
A28: sav05 | B28: 떠돌이 서커스 | C28: 1 | D28: 표를 산다 | E28: 금화 −8 | F28: 0 | G28: -1 | H28: 0 | I28: 현재 -1 | J28: 시간:지금소비
A29: sav05 | B29: 떠돌이 서커스 | C29: 2 | D29: 이번엔 안 간다 | E29: 금화 그대로 | F29: 0 | G29: 0 | H29: 0 | I29: 성향 무관
A30: sav05 | B30: 떠돌이 서커스 | C30: 3 | D30: 마지막 날 싼 표를 산다 | E30: 금화 −3, 하루 기다리기 | F30: 0 | G30: 1 | H30: 0 | I30: 미래 +1 | J30: 시간:지금소비 시간:기다림·떼어둠
A31: sav06 | B31: 흉년의 이웃 섬 | C31: 1 | D31: 광을 한 번 더 점검하고 틈을 막는다 | E31: 금화 −4 | F31: 0 | G31: 1 | H31: 0 | I31: 미래 +1 | J31: 위험:보관
A32: sav06 | B32: 흉년의 이웃 섬 | C32: 2 | D32: 남는 곡식을 비싸게 판다 | E32: 곡식 −10, 금화 +15 | F32: 0 | G32: -1 | H32: 0 | I32: 현재 -1 | J32: 시간:지금소비
A33: sav06 | B33: 흉년의 이웃 섬 | C33: 3 | D33: 아무것도 안 한다 | F33: 0 | G33: 1 | H33: 0 | I33: 미래 +1
A34: sav07 | B34: 대장간 화재 | C34: 1 | D34: 물을 퍼 나른다 | E34: 곡식 −6 | F34: 0 | G34: 0 | H34: 0 | I34: 성향 무관 | J34: 시간:지금소비 시간:수동
A35: sav07 | B35: 대장간 화재 | C35: 2 | D35: 금화로 소방대를 부른다 | E35: 금화 −8 | F35: 0 | G35: 0 | H35: 0 | I35: 성향 무관 | J35: 시간:지금소비 시간:수동
A36: sav08 | B36: 새로 온 가족 | C36: 1 | D36: 받아들인다 | E36: 올겨울 식량 +4, 내년부터 수확 +4 | F36: 0 | G36: 1 | H36: 0 | I36: 미래 +1 | J36: 시간:나중보상
A37: sav08 | B37: 새로 온 가족 | C37: 2 | D37: 다음 해에 오라고 한다 | F37: 0 | G37: -1 | H37: 0 | I37: 현재 -1
A38: sav09 | B38: 돼지 저금통 조개 | C38: 1 | D38: 금화 6닢을 넣고 봉한다 | E38: 금화 −6, 내년 가을에 돌려받음 | F38: 0 | G38: 1 | H38: 0 | I38: 미래 +1 | J38: 시간:나중보상
A39: sav09 | B39: 돼지 저금통 조개 | C39: 2 | D39: 필요 없다 | E39: 금고가 있잖아 | F39: 0 | G39: -1 | H39: 0 | I39: 현재 -1
A40: cmp01 | B40: 길드 금고의 약속 | C40: 1 | D40: 금화 10닢을 맡긴다 | E40: 이번 가을에 11닢으로 | F40: 0 | G40: 1 | H40: 0 | I40: 미래 +1 | J40: 시간:나중보상
...

Sheet 순찰 소문 · 추가 선택지
A1: 카드 ID | B1: 제목 | C1: 기본 덱 | D1: 순찰 소문 | E1: ✨추가 선택지 | F1: 효과 | G1: 결과 문장 | H1: 성향 점수 (위험/시간/판단) | I1: 검토 의견
A2: due02 | B2: 장부의 날 바로 전 | C2: Y | D2: 금고 안 금화는 내일 장부의 날 몫과 딱 같아요. 1닢도 남지 않아요. | E2: 장부의 날 몫을 따로 떼어 두고 남는지 본다 | F2: 변화 없음 (연대기에 남음) | G2: 장부의 날 몫을 주머니에 따로 넣었어요. 남는 게 없네요. 구두는 다음에 봐요. | H2: 0/1/-1
A3: grt01 | B3: 친구 영주의 부탁 | C3: Y | D3: 보증인이 되면, 친구가 못 갚을 때 그 빚을 대신 갚아야 해요. 친구 섬도 올해 흉년이에요. | E3: 보증 대신 곡식 6섬을 그냥 준다 | F3: 곡식 -6 · 신뢰 +1 | G3: "이름은 못 써 주지만, 이건 그냥 가져가." 소식을 들은 길드 상인이 고개를 끄덕였어요. | H3: -1/0/-1
A4: sav01 | B4: 할머니의 항아리 | C4: Y | D4: 섬사람들 말로는, '남으면 넣지' 한 집은 항아리가 늘 비어 있었대요. | E4: 곡식 3섬만 먼저 넣는다 | F4: 곡식 -3 · 다음 가을 곡식 +3 | G4: 작은 한 줌이지만 먼저 넣었어요. 뚜껑을 닫으니 꺼내 먹을 생각도 안 나요. | H4: 0/1/-1
A5: v3carriage | B5: 왕도의 마차 장수 | C5: Y | D5: 이 장수는 다른 섬 세 곳에도 마차를 팔았는데, 다 항구 옆에 세워져 있대요. | E5: 마차 대신 섬에 길부터 놓을 수 있는지 묻는다 | F5: 변화 없음 (연대기에 남음) | G5: 장수가 머리를 긁적였어요. "길이요? 그건 제 장사가 아닌데요." 금화 15닢은 금고에 남았고, 길을 놓을 생각은 연대기에 남았어요. | H5: 0/1/-1
A6: v3guild | B6: 길드 상인의 제안 | C6: Y | D6: 길드 서기 말로는, 세 가을에 나눠 갚으면 받은 곡식보다 더 많이 갚게 된대요. | E6: 절반(10섬)만 외상으로 받는다 | F6: 외상 10섬 · 3가을 나눠 갚기 | G6: 필요한 만큼만 받았어요. 장부에는 절반만 올랐어요. 매 가을 {pay}닢씩 갚아요. | H6: 0/0/-1
A7: v3neighbor | B7: 이웃 섬 영주 | C7: Y | D7: 이웃 섬 창고를 본 어부 말로는, 그 섬 창고도 거의 비었대요. | E7: 5섬만 빌려준다 | F7: 곡식 5 걸기 · 70%로 6 돌려받음 | G7: 곡식 5섬만 실어 보냈어요. 못 받아도 겨울은 버틸 만큼이에요. | H7: 0/0/-1
A8: bud04 | B8: 가을 장부의 날 계산 | C8: Y | D8: 장부의 날에 못 낸 섬은 길드 신뢰가 깎였대요.
A9: cc10 | B9: 한도를 다 쓸까 | C9: Y | D9: 섬 기록을 보니, 한도를 꽉 채운 영주들은 급한 일이 생겨도 인장을 못 썼대요.
A10: cmp01 | B10: 길드 금고의 약속 | C10: Y | D10: 길드 금고는 백 년째 문을 열었고, 약속을 어긴 적이 없대요.
A11: cmp02 | B11: 두 번 맡기기 | C11: Y | D11: 길드 장부를 보니, 오래 맡길수록 늘어난 금화에 또 얹혀서 점점 빨리 불어나요.
A12: cmp05 | B12: 두 가지 선물 | C12: Y | D12: 길드장은 약속 증서를 한 번도 어긴 적이 없대요. 내년 가을엔 정말 15닢이에요.
A13: con02 | B13: 인장 없는 장부 | C13: Y | D13: 이 상인과 거래한 섬의 장부를 보니, 나중에 얹는 몫이 몰래 커져 있었대요.
A14: cor01 | B14: 태풍 하나, 피해 셋 | C14: Y | D14: 작년 태풍 때 바다 벌이만 하던 섬은 한 해 금화 벌이가 거의 없었대요.
A15: crd03 | B15: 급한 배 수리 | C15: Y | D15: 배가 없으면 가을 곡식 판매가 통째로 사라져요. 한 해 금화 벌이가 거기 달려 있어요.
A16: crd06 | B16: 빚 갚으려 빚 내기 | C16: Y | D16: 이 대부업자에게 빌린 섬들은 다음 해에 더 큰 빚을 졌대요. 길드는 미리 말하면 기다려 준 적이 많대요.
A17: div01 | B17: 달걀 바구니 | C17: Y | D17: 아침에 비가 와서, 시장 가는 언덕길이 진흙탕이래요.
A18: div02 | B18: 배 두 척에 나눠 싣기 | C18: Y | D18: 뱃사람들 말로는, 거친 바다에서 두 척이 한꺼번에 가라앉는 일은 드물대요.
A19: inc03 | B19: 가판대 하나 | C19: Y | D19: 가판대는 두 해 동안 가을마다 4닢, 모두 8닢을 벌어 줘요. 짓는 값과 딱 같아요.
... A34: v3trade | B34: 무역선 선장 | C34: Y | D34: 항구 기록을 보니, 이 선장의 배는 지난 열 번 중 다섯 번만 돌아왔어요.

Sheet 개념별 카드 수
A1: 금융 개념 | B1: 뜻(연대기 문구) | C1: 주개념 카드 수 | D1: 기본 덱 안의 카드 수
A2: 저축 · 비상금 | B2: 쓰고 남은 게 아니라, 먼저 떼어 둔 것이 나를 지켜요 | C2: =COUNTIF('카드 목록'!$C$2:$C$162,A2) | D2: =COUNTIFS('카드 목록'!$C$2:$C$162,A2,'카드 목록'!$G$2:$G$162,"Y")
A3: 이자 · 복리 | B3: 늘어난 돈에 또 이자가 붙어요. 시간이 일을 해요 | C3: =COUNTIF('카드 목록'!$C$2:$C$162,A3) | D3: =COUNTIFS('카드 목록'!$C$2:$C$162,A3,'카드 목록'!$G$2:$G$162,"Y")
A4: 보험 | B4: 작은 비용을 미리 내고 큰 손실을 나눠 져요 | C4: =COUNTIF('카드 목록'!$C$2:$C$162,A4) | D4: =COUNTIFS('카드 목록'!$C$2:$C$162,A4,'카드 목록'!$G$2:$G$162,"Y")
A5: 분산 | B5: 한 바구니에 달걀을 다 담지 않기 | C5: =COUNTIF('카드 목록'!$C$2:$C$162,A5) | D5: =COUNTIFS('카드 목록'!$C$2:$C$162,A5,'카드 목록'!$G$2:$G$162,"Y")
A6: 신용 · 대출 | B6: 빚은 나중의 나와 한 약속. 이자는 빌린 값이에요 | C6: =COUNTIF('카드 목록'!$C$2:$C$162,A6) | D6: =COUNTIFS('카드 목록'!$C$2:$C$162,A6,'카드 목록'!$G$2:$G$162,"Y")
A7: 할부 | B7: 나눠 내면 한 번의 부담은 작지만 총액과 기간이 늘어요 | C7: =COUNTIF('카드 목록'!$C$2:$C$162,A7) | D7: =COUNTIFS('카드 목록'!$C$2:$C$162,A7,'카드 목록'!$G$2:$G$162,"Y")
A8: 결제일 | B8: 정해진 날 돈이 빠져나가요. 그날 금고를 비워 두면 안 돼요 | C8: =COUNTIF('카드 목록'!$C$2:$C$162,A8) | D8: =COUNTIFS('카드 목록'!$C$2:$C$162,A8,'카드 목록'!$G$2:$G$162,"Y")
A9: 신용 한도 | B9: 믿음만큼만 빌릴 수 있어요. 한도는 내 돈이 아니에요 | C9: =COUNTIF('카드 목록'!$C$2:$C$162,A9) | D9: =COUNTIFS('카드 목록'!$C$2:$C$162,A9,'카드 목록'!$G$2:$G$162,"Y")
A10: 연체 · 신용점수 | B10: 약속을 어긴 기록은 오래 남아요 | C10: =COUNTIF('카드 목록'!$C$2:$C$162,A10) | D10: =COUNTIFS('카드 목록'!$C$2:$C$162,A10,'카드 목록'!$G$2:$G$162,"Y")
A11: 기회비용 | B11: 하나를 고르면 다른 하나를 포기해요 | C11: =COUNTIF('카드 목록'!$C$2:$C$162,A11) | D11: =COUNTIFS('카드 목록'!$C$2:$C$162,A11,'카드 목록'!$G$2:$G$162,"Y")
A12: 필요 vs 욕구 | B12: 갖고 싶은 것과 꼭 필요한 것은 달라요 | C12: =COUNTIF('카드 목록'!$C$2:$C$162,A12) | D12: =COUNTIFS('카드 목록'!$C$2:$C$162,A12,'카드 목록'!$G$2:$G$162,"Y")
A13: 예산 | B13: 쓰기 전에 미래 몫부터 정해요 | C13: =COUNTIF('카드 목록'!$C$2:$C$162,A13) | D13: =COUNTIFS('카드 목록'!$C$2:$C$162,A13,'카드 목록'!$G$2:$G$162,"Y")
... A32: 연회비 · 수수료 | B32: 혜택보다 비용이 크면 손해예요 | C32: =COUNTIF('카드 목록'!$C$2:$C$162,A32) | D32: =COUNTIFS('카드 목록'!$C$2:$C$162,A32,'카드 목록'!$G$2:$G$162,"Y")
A33: 합계 | C33: =SUM(C2:C32) | D33: =SUM(D2:D32)

Sheet 새 카드 제안
A1: 제안자 | B1: 숨은 개념 | C1: 계절 이벤트 | D1: 난이도(1~3) | E1: 제목·손님 | F1: 상황(2~3문장) | G1: 선택지 1 | H1: 결과 1 | I1: 선택지 2 | J1: 결과 2 | K1: 선택지 3 | L1: 결과 3 | M1: 선생님용 해설 | N1: 메모
A2: (예시) | B2: 보험 | C2: 태풍 | D2: 2 | E2: 🛶 뗏목 조합 | F2: 어부들이 모여 말해요. "태풍에 배가 부서지면 서로 뗏목을 빌려주자! 대신 매 가을 곡식 2섬씩 모으자." | G2: 조합에 들어간다 [곡식 −2, 태풍 대비] | H2: 어부들이 손을 모았어요. 혼자가 아니라서 든든해요. | I2: 들어가지 않는다 | J2: 곡식 2섬을 아꼈어요. 올겨울 바다가 조용하길 바라요. | M2: 보험의 원리 — 여럿이 조금씩 내서 운 나쁜 한 명의 큰 손실을 나눠 진다. | N2: 예시 행이에요. 지우지 말고 아래부터 적어 주세요.
